Workbook

Sheet Base versus Growth
A1: Base versus Growth
A2: Mend — Forecast and runway · Base
A4: Variable / dimension | B4: 2026-10 | C4: 2026-10 > Growth | D4: 2026-11 | E4: 2026-11 > Growth | F4: 2026-12 | G4: 2026-12 > Growth | H4: 2027-01 | I4: 2027-01 > Growth | J4: 2027-02 | K4: 2027-02 > Growth | L4: 2027-03 | M4: 2027-03 > Growth | N4: 2027-04 | O4: 2027-04 > Growth | P4: 2027-05 | Q4: 2027-05 > Growth | R4: 2027-06 | S4: 2027-06 > Growth | T4: 2027-07 | U4: 2027-07 > Growth | V4: 2027-08 | W4: 2027-08 > Growth | X4: 2027-09 | Y4: 2027-09 > Growth | Z4: 2027-10 | AA4: 2027-10 > Growth | AB4: 2027-11 | AC4: 2027-11 > Growth | AD4: 2027-12 | AE4: 2027-12 > Growth | AF4: 2028-01 | AG4: 2028-01 > Growth | AH4: 2028-02 | AI4: 2028-02 > Growth | AJ4: 2028-03 | AK4: 2028-03 > Growth
A5: Paying teams | B5: =IF('Model inputs'!U40="","",'Model inputs'!U40) -> 50 | C5: =IF('Model inputs'!U41="","",'Model inputs'!U41) -> 50 | D5: ='Base versus Growth'!B5*(1+'Model inputs'!U30) -> 50 | E5: ='Base versus Growth'!C5*(1+'Model inputs'!U31) -> 55 | F5: ='Base versus Growth'!D5*(1+'Model inputs'!U30) -> 50 | G5: ='Base versus Growth'!E5*(1+'Model inputs'!U31) -> 60.5 | H5: ='Base versus Growth'!F5*(1+'Model inputs'!U30) -> 50 | I5: ='Base versus Growth'!G5*(1+'Model inputs'!U31) -> 66.55 | J5: ='Base versus Growth'!H5*(1+'Model inputs'!U30) -> 50 | K5: ='Base versus Growth'!I5*(1+'Model inputs'!U31) -> 73.205 | L5: ='Base versus Growth'!J5*(1+'Model inputs'!U30) -> 50 | M5: ='Base versus Growth'!K5*(1+'Model inputs'!U31) -> 80.5255 | N5: ='Base versus Growth'!L5*(1+'Model inputs'!U30) -> 50 | O5: ='Base versus Growth'!M5*(1+'Model inputs'!U31) -> 88.57805 | P5: ='Base versus Growth'!N5*(1+'Model inputs'!U30) -> 50 | Q5: ='Base versus Growth'!O5*(1+'Model inputs'!U31) -> 97.435855 | R5: ='Base versus Growth'!P5*(1+'Model inputs'!U30) -> 50 | S5: ='Base versus Growth'!Q5*(1+'Model inputs'!U31) -> 107.17944 | T5: ='Base versus Growth'!R5*(1+'Model inputs'!U30) -> 50 | U5: ='Base versus Growth'!S5*(1+'Model inputs'!U31) -> 117.89738 | V5: ='Base versus Growth'!T5*(1+'Model inputs'!U30) -> 50 | W5: ='Base versus Growth'!U5*(1+'Model inputs'!U31) -> 129.68712 | X5: ='Base versus Growth'!V5*(1+'Model inputs'!U30) -> 50 | Y5: ='Base versus Growth'!W5*(1+'Model inputs'!U31) -> 142.65584 | Z5: ='Base versus Growth'!X5*(1+'Model inputs'!U30) -> 50 | AA5: ='Base versus Growth'!Y5*(1+'Model inputs'!U31) -> 156.92142 | AB5: ='Base versus Growth'!Z5*(1+'Model inputs'!U30) -> 50 | AC5: ='Base versus Growth'!AA5*(1+'Model inputs'!U31) -> 172.61356 | AD5: ='Base versus Growth'!AB5*(1+'Model inputs'!U30) -> 50 | AE5: ='Base versus Growth'!AC5*(1+'Model inputs'!U31) -> 189.87492 | AF5: ='Base versus Growth'!AD5*(1+'Model inputs'!U30) -> 50 | AG5: ='Base versus Growth'!AE5*(1+'Model inputs'!U31) -> 208.86241 | AH5: ='Base versus Growth'!AF5*(1+'Model inputs'!U30) -> 50 | AI5: ='Base versus Growth'!AG5*(1+'Model inputs'!U31) -> 229.74865 | AJ5: ='Base versus Growth'!AH5*(1+'Model inputs'!U30) -> 50 | AK5: ='Base versus Growth'!AI5*(1+'Model inputs'!U31) -> 252.72351
A6: Monthly revenue | B6: ='Base versus Growth'!B5*'Model inputs'!U35 -> 2450 | C6: ='Base versus Growth'!C5*'Model inputs'!U36 -> 2450 | D6: ='Base versus Growth'!D5*'Model inputs'!U35 -> 2450 | E6: ='Base versus Growth'!E5*'Model inputs'!U36 -> 2695 | F6: ='Base versus Growth'!F5*'Model inputs'!U35 -> 2450 | G6: ='Base versus Growth'!G5*'Model inputs'!U36 -> 2964.5 | H6: ='Base versus Growth'!H5*'Model inputs'!U35 -> 2450 | I6: ='Base versus Growth'!I5*'Model inputs'!U36 -> 3260.95 | J6: ='Base versus Growth'!J5*'Model inputs'!U35 -> 2450 | K6: ='Base versus Growth'!K5*'Model inputs'!U36 -> 3587.045 | L6: ='Base versus Growth'!L5*'Model inputs'!U35 -> 2450 | M6: ='Base versus Growth'!M5*'Model inputs'!U36 -> 3945.7495 | N6: ='Base versus Growth'!N5*'Model inputs'!U35 -> 2450 | O6: ='Base versus Growth'!O5*'Model inputs'!U36 -> 4340.3245 | P6: ='Base versus Growth'!P5*'Model inputs'!U35 -> 2450 | Q6: ='Base versus Growth'!Q5*'Model inputs'!U36 -> 4774.3569 | R6: ='Base versus Growth'!R5*'Model inputs'!U35 -> 2450 | S6: ='Base versus Growth'!S5*'Model inputs'!U36 -> 5251.7926 | T6: ='Base versus Growth'!T5*'Model inputs'!U35 -> 2450 | U6: ='Base versus Growth'!U5*'Model inputs'!U36 -> 5776.9718 | V6: ='Base versus Growth'!V5*'Model inputs'!U35 -> 2450 | W6: ='Base versus Growth'!W5*'Model inputs'!U36 -> 6354.669 | X6: ='Base versus Growth'!X5*'Model inputs'!U35 -> 2450 | Y6: ='Base versus Growth'!Y5*'Model inputs'!U36 -> 6990.1359 | Z6: ='Base versus Growth'!Z5*'Model inputs'!U35 -> 2450 | AA6: ='Base versus Growth'!AA5*'Model inputs'!U36 -> 7689.1495 | AB6: ='Base versus Growth'!AB5*'Model inputs'!U35 -> 2450 | AC6: ='Base versus Growth'!AC5*'Model inputs'!U36 -> 8458.0645 | AD6: ='Base versus Growth'!AD5*'Model inputs'!U35 -> 2450 | AE6: ='Base versus Growth'!AE5*'Model inputs'!U36 -> 9303.8709 | AF6: ='Base versus Growth'!AF5*'Model inputs'!U35 -> 2450 | AG6: ='Base versus Growth'!AG5*'Model inputs'!U36 -> 10234.258 | AH6: ='Base versus Growth'!AH5*'Model inputs'!U35 -> 2450 | AI6: ='Base versus Growth'!AI5*'Model inputs'!U36 -> 11257.684 | AJ6: ='Base versus Growth'!AJ5*'Model inputs'!U35 -> 2450 | AK6: ='Base versus Growth'!AK5*'Model inputs'!U36 -> 12383.452
A7: Gross margin | B7: =IFERROR('18-month forecast'!B11/'Base versus Growth'!B6,"") -> 0.30612245 | C7: =IFERROR('Model inputs'!C21/'Base versus Growth'!C6,"") -> 0.30612245 | D7: =IFERROR('18-month forecast'!C11/'Base versus Growth'!D6,"") -> 0.30612245 | E7: =IFERROR('Model inputs'!D21/'Base versus Growth'!E6,"") -> 0.3135436 | F7: =IFERROR('18-month forecast'!D11/'Base versus Growth'!F6,"") -> 0.30612245 | G7: =IFERROR('Model inputs'!E21/'Base versus Growth'!G6,"") -> 0.3202901 | H7: =IFERROR('18-month forecast'!E11/'Base versus Growth'!H6,"") -> 0.30612245 | I7: =IFERROR('Model inputs'!F21/'Base versus Growth'!I6,"") -> 0.32642328 | J7: =IFERROR('18-month forecast'!F11/'Base versus Growth'!J6,"") -> 0.30612245 | K7: =IFERROR('Model inputs'!G21/'Base versus Growth'!K6,"") -> 0.3319989 | L7: =IFERROR('18-month forecast'!G11/'Base versus Growth'!L6,"") -> 0.30612245 | M7: =IFERROR('Model inputs'!H21/'Base versus Growth'!M6,"") -> 0.33706765 | N7: =IFERROR('18-month forecast'!H11/'Base versus Growth'!N6,"") -> 0.30612245 | O7: =IFERROR('Model inputs'!I21/'Base versus Growth'!O6,"") -> 0.3416756 | P7: =IFERROR('18-month forecast'!I11/'Base versus Growth'!P6,"") -> 0.30612245 | Q7: =IFERROR('Model inputs'!J21/'Base versus Growth'!Q6,"") -> 0.34586464 | R7: =IFERROR('18-month forecast'!J11/'Base versus Growth'!R6,"") -> 0.30612245 | S7: =IFERROR('Model inputs'!K21/'Base versus Growth'!S6,"") -> 0.34967287 | T7: =IFERROR('18-month forecast'!K11/'Base versus Growth'!T6,"") -> 0.30612245 | U7: =IFERROR('Model inputs'!L21/'Base versus Growth'!U6,"") -> 0.35313489 | V7: =IFERROR('18-month forecast'!L11/'Base versus Growth'!V6,"") -> 0.30612245 | W7: =IFERROR('Model inputs'!M21/'Base versus Growth'!W6,"") -> 0.35628218 | X7: =IFERROR('18-month forecast'!M11/'Base versus Growth'!X6,"") -> 0.30612245 | Y7: =IFERROR('Model inputs'!N21/'Base versus Growth'!Y6,"") -> 0.35914336 | Z7: =IFERROR('18-month forecast'!N11/'Base versus Growth'!Z6,"") -> 0.30612245 | AA7: =IFERROR('Model inputs'!O21/'Base versus Growth'!AA6,"") -> 0.36174442 | AB7: =IFERROR('18-month forecast'!O11/'Base versus Growth'!AB6,"") -> 0.30612245 | AC7: =IFERROR('Model inputs'!P21/'Base versus Growth'!AC6,"") -> 0.36410903 | AD7: =IFERROR('18-month forecast'!P11/'Base versus Growth'!AD6,"") -> 0.30612245 | AE7: =IFERROR('Model inputs'!Q21/'Base versus Growth'!AE6,"") -> 0.36625867 | AF7: =IFERROR('18-month forecast'!Q11/'Base versus Growth'!AF6,"") -> 0.30612245 | AG7: =IFERROR('Model inputs'!R21/'Base versus Growth'!AG6,"") -> 0.36821289 | AH7: =IFERROR('18-month forecast'!R11/'Base versus Growth'!AH6,"") -> 0.30612245 | AI7: =IFERROR('Model inputs'!S21/'Base versus Growth'!AI6,"") -> 0.36998946 | AJ7: =IFERROR('18-month forecast'!S11/'Base versus Growth'!AJ6,"") -> 0.30612245 | AK7: =IFERROR('Model inputs'!T21/'Base versus Growth'!AK6,"") -> 0.37160452
A8: Net cash flow | B8: ='18-month forecast'!B11-'18-month forecast'!B13 -> 750 | C8: ='Model inputs'!C21-'Model inputs'!C19 -> 750 | D8: ='18-month forecast'!C11-'18-month forecast'!C13 -> 750 | E8: ='Model inputs'!D21-'Model inputs'!D19 -> 845 | F8: ='18-month forecast'!D11-'18-month forecast'!D13 -> 750 | G8: ='Model inputs'!E21-'Model inputs'!E19 -> 949.5 | H8: ='18-month forecast'!E11-'18-month forecast'!E13 -> 750 | I8: ='Model inputs'!F21-'Model inputs'!F19 -> 1064.45 | J8: ='18-month forecast'!F11-'18-month forecast'!F13 -> 750 | K8: ='Model inputs'!G21-'Model inputs'!G19 -> 1190.895 | L8: ='18-month forecast'!G11-'18-month forecast'!G13 -> 750 | M8: ='Model inputs'!H21-'Model inputs'!H19 -> 1329.9845 | N8: ='18-month forecast'!H11-'18-month forecast'!H13 -> -7250 | O8: ='Model inputs'!I21-'Model inputs'!I19 -> -6517.017 | P8: ='18-month forecast'!I11-'18-month forecast'!I13 -> -7250 | Q8: ='Model inputs'!J21-'Model inputs'!J19 -> -6348.7188 | R8: ='18-month forecast'!J11-'18-month forecast'!J13 -> -7250 | S8: ='Model inputs'!K21-'Model inputs'!K19 -> -6163.5906 | T8: ='18-month forecast'!K11-'18-month forecast'!K13 -> -7250 | U8: ='Model inputs'!L21-'Model inputs'!L19 -> -5959.9497 | V8: ='18-month forecast'!L11-'18-month forecast'!L13 -> -7250 | W8: ='Model inputs'!M21-'Model inputs'!M19 -> -5735.9447 | X8: ='18-month forecast'!M11-'18-month forecast'!M13 -> -7250 | Y8: ='Model inputs'!N21-'Model inputs'!N19 -> -5489.5391 | Z8: ='18-month forecast'!N11-'18-month forecast'!N13 -> -7250 | AA8: ='Model inputs'!O21-'Model inputs'!O19 -> -5218.493 | AB8: ='18-month forecast'!O11-'18-month forecast'!O13 -> -7250 | AC8: ='Model inputs'!P21-'Model inputs'!P19 -> -4920.3423 | AD8: ='18-month forecast'!P11-'18-month forecast'!P13 -> -7250 | AE8: ='Model inputs'!Q21-'Model inputs'!Q19 -> -4592.3766 | AF8: ='18-month forecast'!Q11-'18-month forecast'!Q13 -> -7250 | AG8: ='Model inputs'!R21-'Model inputs'!R19 -> -4231.6142 | AH8: ='18-month forecast'!R11-'18-month forecast'!R13 -> -7250 | AI8: ='Model inputs'!S21-'Model inputs'!S19 -> -3834.7757 | AJ8: ='18-month forecast'!S11-'18-month forecast'!S13 -> -7250 | AK8: ='Model inputs'!T21-'Model inputs'!T19 -> -3398.2532
A9: Closing cash | B9: =IF(IF(DATE(2026,10,1)=DATE(2026,10,1),IF('Model inputs'!U38="","",'Model inputs'!U38),IF('Model inputs'!B6="","",'Model inputs'!B6))="",0,IF(DATE(2026,10,1)=DATE(2026,10,1),IF('Model inputs'!U38="","",'Model inputs'!U38),IF('Model inputs'!B6="","",'Model inputs'!B6)))+'Base versus Growth'!B8 -> 10750 | C9: =IF(IF(DATE(2026,10,1)=DATE(2026,10,1),IF('Model inputs'!U39="","",'Model inputs'!U39),IF('Model inputs'!B7="","",'Model inputs'!B7))="",0,IF(DATE(2026,10,1)=DATE(2026,10,1),IF('Model inputs'!U39="","",'Model inputs'!U39),IF('Model inputs'!B7="","",'Model inputs'!B7)))+'Base versus Growth'!C8 -> 10750 | D9: =IF(IF(DATE(2026,11,1)=DATE(2026,10,1),IF('Model inputs'!U38="","",'Model inputs'!U38),IF('Base versus Growth'!B9="","",'Base versus Growth'!B9))="",0,IF(DATE(2026,11,1)=DATE(2026,10,1),IF('Model inputs'!U38="","",'Model inputs'!U38),IF('Base versus Growth'!B9="","",'Base versus Growth'!B9)))+'Base versus Growth'!D8 -> 11500 | E9: =IF(IF(DATE(2026,11,1)=DATE(2026,10,1),IF('Model inputs'!U39="","",'Model inputs'!U39),IF('Base versus Growth'!C9="","",'Base versus Growth'!C9))="",0,IF(DATE(2026,11,1)=DATE(2026,10,1),IF('Model inputs'!U39="","",'Model inputs'!U39),IF('Base versus Growth'!C9="","",'Base versus Growth'!C9)))+'Base versus Growth'!E8 -> 11595 | F9: =IF(IF(DATE(2026,12,1)=DATE(2026,10,1),IF('Model inputs'!U38="","",'Model inputs'!U38),IF('Base versus Growth'!D9="","",'Base versus Growth'!D9))="",0,IF(DATE(2026,12,1)=DATE(2026,10,1),IF('Model inputs'!U38="","",'Model inputs'!U38),IF('Base versus Growth'!D9="","",'Base versus Growth'!D9)))+'Base versus Growth'!F8 -> 12250 | G9: =IF(IF(DATE(2026,12,1)=DATE(2026,10,1),IF('Model inputs'!U39="","",'Model inputs'!U39),IF('Base versus Growth'!E9="","",'Base versus Growth'!E9))="",0,IF(DATE(2026,12,1)=DATE(2026,10,1),IF('Model inputs'!U39="","",'Model inputs'!U39),IF('Base versus Growth'!E9="","",'Base versus Growth'!E9)))+'Base versus Growth'!G8 -> 12544.5 | H9: =IF(IF(DATE(2027,1,1)=DATE(2026,10,1),IF('Model inputs'!U38="","",'Model inputs'!U38),IF('Base versus Growth'!F9="","",'Base versus Growth'!F9))="",0,IF(DATE(2027,1,1)=DATE(2026,10,1),IF('Model inputs'!U38="","",'Model inputs'!U38),IF('Base versus Growth'!F9="","",'Base versus Growth'!F9)))+'Base versus Growth'!H8 -> 13000 | I9: =IF(IF(DATE(2027,1,1)=DATE(2026,10,1),IF('Model inputs'!U39="","",'Model inputs'!U39),IF('Base versus Growth'!G9="","",'Base versus Growth'!G9))="",0,IF(DATE(2027,1,1)=DATE(2026,10,1),IF('Model inputs'!U39="","",'Model inputs'!U39),IF('Base versus Growth'!G9="","",'Base versus Growth'!G9)))+'Base versus Growth'!I8 -> 13608.95 | J9: =IF(IF(DATE(2027,2,1)=DATE(2026,10,1),IF('Model inputs'!U38="","",'Model inputs'!U38),IF('Base versus Growth'!H9="","",'Base versus Growth'!H9))="",0,IF(DATE(2027,2,1)=DATE(2026,10,1),IF('Model inputs'!U38="","",'Model inputs'!U38),IF('Base versus Growth'!H9="","",'Base versus Growth'!H9)))+'Base versus Growth'!J8 -> 13750 | K9: =IF(IF(DATE(2027,2,1)=DATE(2026,10,1),IF('Model inputs'!U39="","",'Model inputs'!U39),IF('Base versus Growth'!I9="","",'Base versus Growth'!I9))="",0,IF(DATE(2027,2,1)=DATE(2026,10,1),IF('Model inputs'!U39="","",'Model inputs'!U39),IF('Base versus Growth'!I9="","",'Base versus Growth'!I9)))+'Base versus Growth'!K8 -> 14799.845 | L9: =IF(IF(DATE(2027,3,1)=DATE(2026,10,1),IF('Model inputs'!U38="","",'Model inputs'!U38),IF('Base versus Growth'!J9="","",'Base versus Growth'!J9))="",0,IF(DATE(2027,3,1)=DATE(2026,10,1),IF('Model inputs'!U38="","",'Model inputs'!U38),IF('Base versus Growth'!J9="","",'Base versus Growth'!J9)))+'Base versus Growth'!L8 -> 14500 | M9: =IF(IF(DATE(2027,3,1)=DATE(2026,10,1),IF('Model inputs'!U39="","",'Model inputs'!U39),IF('Base versus Growth'!K9="","",'Base versus Growth'!K9))="",0,IF(DATE(2027,3,1)=DATE(2026,10,1),IF('Model inputs'!U39="","",'Model inputs'!U39),IF('Base versus Growth'!K9="","",'Base versus Growth'!K9)))+'Base versus Growth'!M8 -> 16129.83 | N9: =IF(IF(DATE(2027,4,1)=DATE(2026,10,1),IF('Model inputs'!U38="","",'Model inputs'!U38),IF('Base versus Growth'!L9="","",'Base versus Growth'!L9))="",0,IF(DATE(2027,4,1)=DATE(2026,10,1),IF('Model inputs'!U38="","",'Model inputs'!U38),IF('Base versus Growth'!L9="","",'Base versus Growth'!L9)))+'Base versus Growth'!N8 -> 7250 | O9: =IF(IF(DATE(2027,4,1)=DATE(2026,10,1),IF('Model inputs'!U39="","",'Model inputs'!U39),IF('Base versus Growth'!M9="","",'Base versus Growth'!M9))="",0,IF(DATE(2027,4,1)=DATE(2026,10,1),IF('Model inputs'!U39="","",'Model inputs'!U39),IF('Base versus Growth'!M9="","",'Base versus Growth'!M9)))+'Base versus Growth'!O8 -> 9612.8125 | P9: =IF(IF(DATE(2027,5,1)=DATE(2026,10,1),IF('Model inputs'!U38="","",'Model inputs'!U38),IF('Base versus Growth'!N9="","",'Base versus Growth'!N9))="",0,IF(DATE(2027,5,1)=DATE(2026,10,1),IF('Model inputs'!U38="","",'Model inputs'!U38),IF('Base versus Growth'!N9="","",'Base versus Growth'!N9)))+'Base versus Growth'!P8 -> 0 | Q9: =IF(IF(DATE(2027,5,1)=DATE(2026,10,1),IF('Model inputs'!U39="","",'Model inputs'!U39),IF('Base versus Growth'!O9="","",'Base versus Growth'!O9))="",0,IF(DATE(2027,5,1)=DATE(2026,10,1),IF('Model inputs'!U39="","",'Model inputs'!U39),IF('Base versus Growth'!O9="","",'Base versus Growth'!O9)))+'Base versus Growth'!Q8 -> 3264.0937 | R9: =IF(IF(DATE(2027,6,1)=DATE(2026,10,1),IF('Model inputs'!U38="","",'Model inputs'!U38),IF('Base versus Growth'!P9="","",'Base versus Growth'!P9))="",0,IF(DATE(2027,6,1)=DATE(2026,10,1),IF('Model inputs'!U38="","",'Model inputs'!U38),IF('Base versus Growth'!P9="","",'Base versus Growth'!P9)))+'Base versus Growth'!R8 -> -7250 | S9: =IF(IF(DATE(2027,6,1)=DATE(2026,10,1),IF('Model inputs'!U39="","",'Model inputs'!U39),IF('Base versus Growth'!Q9="","",'Base versus Growth'!Q9))="",0,IF(DATE(2027,6,1)=DATE(2026,10,1),IF('Model inputs'!U39="","",'Model inputs'!U39),IF('Base versus Growth'!Q9="","",'Base versus Growth'!Q9)))+'Base versus Growth'!S8 -> -2899.4969 | T9: =IF(IF(DATE(2027,7,1)=DATE(2026,10,1),IF('Model inputs'!U38="","",'Model inputs'!U38),IF('Base versus Growth'!R9="","",'Base versus Growth'!R9))="",0,IF(DATE(2027,7,1)=DATE(2026,10,1),IF('Model inputs'!U38="","",'Model inputs'!U38),IF('Base versus Growth'!R9="","",'Base versus Growth'!R9)))+'Base versus Growth'!T8 -> -14500 | U9: =IF(IF(DATE(2027,7,1)=DATE(2026,10,1),IF('Model inputs'!U39="","",'Model inputs'!U39),IF('Base versus Growth'!S9="","",'Base versus Growth'!S9))="",0,IF(DATE(2027,7,1)=DATE(2026,10,1),IF('Model inputs'!U39="","",'Model inputs'!U39),IF('Base versus Growth'!S9="","",'Base versus Growth'!S9)))+'Base versus Growth'!U8 -> -8859.4466 | V9: =IF(IF(DATE(2027,8,1)=DATE(2026,10,1),IF('Model inputs'!U38="","",'Model inputs'!U38),IF('Base versus Growth'!T9="","",'Base versus Growth'!T9))="",0,IF(DATE(2027,8,1)=DATE(2026,10,1),IF('Model inputs'!U38="","",'Model inputs'!U38),IF('Base versus Growth'!T9="","",'Base versus Growth'!T9)))+'Base versus Growth'!V8 -> -21750 | W9: =IF(IF(DATE(2027,8,1)=DATE(2026,10,1),IF('Model inputs'!U39="","",'Model inputs'!U39),IF('Base versus Growth'!U9="","",'Base versus Growth'!U9))="",0,IF(DATE(2027,8,1)=DATE(2026,10,1),IF('Model inputs'!U39="","",'Model inputs'!U39),IF('Base versus Growth'!U9="","",'Base versus Growth'!U9)))+'Base versus Growth'!W8 -> -14595.391 | X9: =IF(IF(DATE(2027,9,1)=DATE(2026,10,1),IF('Model inputs'!U38="","",'Model inputs'!U38),IF('Base versus Growth'!V9="","",'Base versus Growth'!V9))="",0,IF(DATE(2027,9,1)=DATE(2026,10,1),IF('Model inputs'!U38="","",'Model inputs'!U38),IF('Base versus Growth'!V9="","",'Base versus Growth'!V9)))+'Base versus Growth'!X8 -> -29000 | Y9: =IF(IF(DATE(2027,9,1)=DATE(2026,10,1),IF('Model inputs'!U39="","",'Model inputs'!U39),IF('Base versus Growth'!W9="","",'Base versus Growth'!W9))="",0,IF(DATE(2027,9,1)=DATE(2026,10,1),IF('Model inputs'!U39="","",'Model inputs'!U39),IF('Base versus Growth'!W9="","",'Base versus Growth'!W9)))+'Base versus Growth'!Y8 -> -20084.93 | Z9: =IF(IF(DATE(2027,10,1)=DATE(2026,10,1),IF('Model inputs'!U38="","",'Model inputs'!U38),IF('Base versus Growth'!X9="","",'Base versus Growth'!X9))="",0,IF(DATE(2027,10,1)=DATE(2026,10,1),IF('Model inputs'!U38="","",'Model inputs'!U38),IF('Base versus Growth'!X9="","",'Base versus Growth'!X9)))+'Base versus Growth'!Z8 -> -36250 | AA9: =IF(IF(DATE(2027,10,1)=DATE(2026,10,1),IF('Model inputs'!U39="","",'Model inputs'!U39),IF('Base versus Growth'!Y9="","",'Base versus Growth'!Y9))="",0,IF(DATE(2027,10,1)=DATE(2026,10,1),IF('Model inputs'!U39="","",'Model inputs'!U39),IF('Base versus Growth'!Y9="","",'Base versus Growth'!Y9)))+'Base versus Growth'!AA8 -> -25303.423 | AB9: =IF(IF(DATE(2027,11,1)=DATE(2026,10,1),IF('Model inputs'!U38="","",'Model inputs'!U38),IF('Base versus Growth'!Z9="","",'Base versus Growth'!Z9))="",0,IF(DATE(2027,11,1)=DATE(2026,10,1),IF('Model inputs'!U38="","",'Model inputs'!U38),IF('Base versus Growth'!Z9="","",'Base versus Growth'!Z9)))+'Base versus Growth'!AB8 -> -43500 | AC9: =IF(IF(DATE(2027,11,1)=DATE(2026,10,1),IF('Model inputs'!U39="","",'Model inputs'!U39),IF('Base versus Growth'!AA9="","",'Base versus Growth'!AA9))="",0,IF(DATE(2027,11,1)=DATE(2026,10,1),IF('Model inputs'!U39="","",'Model inputs'!U39),IF('Base versus Growth'!AA9="","",'Base versus Growth'!AA9)))+'Base versus Growth'!AC8 -> -30223.766 | AD9: =IF(IF(DATE(2027,12,1)=DATE(2026,10,1),IF('Model inputs'!U38="","",'Model inputs'!U38),IF('Base versus Growth'!AB9="","",'Base versus Growth'!AB9))="",0,IF(DATE(2027,12,1)=DATE(2026,10,1),IF('Model inputs'!U38="","",'Model inputs'!U38),IF('Base versus Growth'!AB9="","",'Base versus Growth'!AB9)))+'Base versus Growth'!AD8 -> -50750 | AE9: =IF(IF(DATE(2027,12,1)=DATE(2026,10,1),IF('Model inputs'!U39="","",'Model inputs'!U39),IF('Base versus Growth'!AC9="","",'Base versus Growth'!AC9))="",0,IF(DATE(2027,12,1)=DATE(2026,10,1),IF('Model inputs'!U39="","",'Model inputs'!U39),IF('Base versus Growth'!AC9="","",'Base versus Growth'!AC9)))+'Base versus Growth'!AE8 -> -34816.142 | AF9: =IF(IF(DATE(2028,1,1)=DATE(2026,10,1),IF('Model inputs'!U38="","",'Model inputs'!U38),IF('Base versus Growth'!AD9="","",'Base versus Growth'!AD9))="",0,IF(DATE(2028,1,1)=DATE(2026,10,1),IF('Model inputs'!U38="","",'Model inputs'!U38),IF('Base versus Growth'!AD9="","",'Base versus Growth'!AD9)))+'Base versus Growth'!AF8 -> -58000 | AG9: =IF(IF(DATE(2028,1,1)=DATE(2026,10,1),IF('Model inputs'!U39="","",'Model inputs'!U39),IF('Base versus Growth'!AE9="","",'Base versus Growth'!AE9))="",0,IF(DATE(2028,1,1)=DATE(2026,10,1),IF('Model inputs'!U39="","",'Model inputs'!U39),IF('Base versus Growth'!AE9="","",'Base versus Growth'!AE9)))+'Base versus Growth'!AG8 -> -39047.757 | AH9: =IF(IF(DATE(2028,2,1)=DATE(2026,10,1),IF('Model inputs'!U38="","",'Model inputs'!U38),IF('Base versus Growth'!AF9="","",'Base versus Growth'!AF9))="",0,IF(DATE(2028,2,1)=DATE(2026,10,1),IF('Model inputs'!U38="","",'Model inputs'!U38),IF('Base versus Growth'!AF9="","",'Base versus Growth'!AF9)))+'Base versus Growth'!AH8 -> -65250 | AI9: =IF(IF(DATE(2028,2,1)=DATE(2026,10,1),IF('Model inputs'!U39="","",'Model inputs'!U39),IF('Base versus Growth'!AG9="","",'Base versus Growth'!AG9))="",0,IF(DATE(2028,2,1)=DATE(2026,10,1),IF('Model inputs'!U39="","",'Model inputs'!U39),IF('Base versus Growth'!AG9="","",'Base versus Growth'!AG9)))+'Base versus Growth'!AI8 -> -42882.532 | AJ9: =IF(IF(DATE(2028,3,1)=DATE(2026,10,1),IF('Model inputs'!U38="","",'Model inputs'!U38),IF('Base versus Growth'!AH9="","",'Base versus Growth'!AH9))="",0,IF(DATE(2028,3,1)=DATE(2026,10,1),IF('Model inputs'!U38="","",'Model inputs'!U38),IF('Base versus Growth'!AH9="","",'Base versus Growth'!AH9)))+'Base versus Growth'!AJ8 -> -72500 | AK9: =IF(IF(DATE(2028,3,1)=DATE(2026,10,1),IF('Model inputs'!U39="","",'Model inputs'!U39),IF('Base versus Growth'!AI9="","",'Base versus Growth'!AI9))="",0,IF(DATE(2028,3,1)=DATE(2026,10,1),IF('Model inputs'!U39="","",'Model inputs'!U39),IF('Base versus Growth'!AI9="","",'Base versus Growth'!AI9)))+'Base versus Growth'!AK8 -> -46280.786

Sheet 18-month forecast
A1: 18-month forecast
A2: Mend — Forecast and runway · Base
A4: Variable / dimension | B4: 2026-10 | C4: 2026-11 | D4: 2026-12 | E4: 2027-01 | F4: 2027-02 | G4: 2027-03 | H4: 2027-04 | I4: 2027-05 | J4: 2027-06 | K4: 2027-07 | L4: 2027-08 | M4: 2027-09 | N4: 2027-10 | O4: 2027-11 | P4: 2027-12 | Q4: 2028-01 | R4: 2028-02 | S4: 2028-03
A5: Paying teams | B5: =IF('Model inputs'!U40="","",'Model inputs'!U40) -> 50 | C5: ='18-month forecast'!B5*(1+'Model inputs'!U30) -> 50 | D5: ='18-month forecast'!C5*(1+'Model inputs'!U30) -> 50 | E5: ='18-month forecast'!D5*(1+'Model inputs'!U30) -> 50 | F5: ='18-month forecast'!E5*(1+'Model inputs'!U30) -> 50 | G5: ='18-month forecast'!F5*(1+'Model inputs'!U30) -> 50 | H5: ='18-month forecast'!G5*(1+'Model inputs'!U30) -> 50 | I5: ='18-month forecast'!H5*(1+'Model inputs'!U30) -> 50 | J5: ='18-month forecast'!I5*(1+'Model inputs'!U30) -> 50 | K5: ='18-month forecast'!J5*(1+'Model inputs'!U30) -> 50 | L5: ='18-month forecast'!K5*(1+'Model inputs'!U30) -> 50 | M5: ='18-month forecast'!L5*(1+'Model inputs'!U30) -> 50 | N5: ='18-month forecast'!M5*(1+'Model inputs'!U30) -> 50 | O5: ='18-month forecast'!N5*(1+'Model inputs'!U30) -> 50 | P5: ='18-month forecast'!O5*(1+'Model inputs'!U30) -> 50 | Q5: ='18-month forecast'!P5*(1+'Model inputs'!U30) -> 50 | R5: ='18-month forecast'!Q5*(1+'Model inputs'!U30) -> 50 | S5: ='18-month forecast'!R5*(1+'Model inputs'!U30) -> 50
A6: Monthly revenue | B6: ='18-month forecast'!B5*'Model inputs'!U35 -> 2450 | C6: ='18-month forecast'!C5*'Model inputs'!U35 -> 2450 | D6: ='18-month forecast'!D5*'Model inputs'!U35 -> 2450 | E6: ='18-month forecast'!E5*'Model inputs'!U35 -> 2450 | F6: ='18-month forecast'!F5*'Model inputs'!U35 -> 2450 | G6: ='18-month forecast'!G5*'Model inputs'!U35 -> 2450 | H6: ='18-month forecast'!H5*'Model inputs'!U35 -> 2450 | I6: ='18-month forecast'!I5*'Model inputs'!U35 -> 2450 | J6: ='18-month forecast'!J5*'Model inputs'!U35 -> 2450 | K6: ='18-month forecast'!K5*'Model inputs'!U35 -> 2450 | L6: ='18-month forecast'!L5*'Model inputs'!U35 -> 2450 | M6: ='18-month forecast'!M5*'Model inputs'!U35 -> 2450 | N6: ='18-month forecast'!N5*'Model inputs'!U35 -> 2450 | O6: ='18-month forecast'!O5*'Model inputs'!U35 -> 2450 | P6: ='18-month forecast'!P5*'Model inputs'!U35 -> 2450 | Q6: ='18-month forecast'!Q5*'Model inputs'!U35 -> 2450 | R6: ='18-month forecast'!R5*'Model inputs'!U35 -> 2450 | S6: ='18-month forecast'!S5*'Model inputs'!U35 -> 2450
A7: Repair rounds delivered | B7: ='18-month forecast'!B5*'Model inputs'!U37 -> 1000 | C7: ='18-month forecast'!C5*'Model inputs'!U37 -> 1000 | D7: ='18-month forecast'!D5*'Model inputs'!U37 -> 1000 | E7: ='18-month forecast'!E5*'Model inputs'!U37 -> 1000 | F7: ='18-month forecast'!F5*'Model inputs'!U37 -> 1000 | G7: ='18-month forecast'!G5*'Model inputs'!U37 -> 1000 | H7: ='18-month forecast'!H5*'Model inputs'!U37 -> 1000 | I7: ='18-month forecast'!I5*'Model inputs'!U37 -> 1000 | J7: ='18-month forecast'!J5*'Model inputs'!U37 -> 1000 | K7: ='18-month forecast'!K5*'Model inputs'!U37 -> 1000 | L7: ='18-month forecast'!L5*'Model inputs'!U37 -> 1000 | M7: ='18-month forecast'!M5*'Model inputs'!U37 -> 1000 | N7: ='18-month forecast'!N5*'Model inputs'!U37 -> 1000 | O7: ='18-month forecast'!O5*'Model inputs'!U37 -> 1000 | P7: ='18-month forecast'!P5*'Model inputs'!U37 -> 1000 | Q7: ='18-month forecast'!Q5*'Model inputs'!U37 -> 1000 | R7: ='18-month forecast'!R5*'Model inputs'!U37 -> 1000 | S7: ='18-month forecast'!S5*'Model inputs'!U37 -> 1000
A8: Monthly model fees | B8: ='18-month forecast'!B7*'Model inputs'!U34 -> 1500 | C8: ='18-month forecast'!C7*'Model inputs'!U34 -> 1500 | D8: ='18-month forecast'!D7*'Model inputs'!U34 -> 1500 | E8: ='18-month forecast'!E7*'Model inputs'!U34 -> 1500 | F8: ='18-month forecast'!F7*'Model inputs'!U34 -> 1500 | G8: ='18-month forecast'!G7*'Model inputs'!U34 -> 1500 | H8: ='18-month forecast'!H7*'Model inputs'!U34 -> 1500 | I8: ='18-month forecast'!I7*'Model inputs'!U34 -> 1500 | J8: ='18-month forecast'!J7*'Model inputs'!U34 -> 1500 | K8: ='18-month forecast'!K7*'Model inputs'!U34 -> 1500 | L8: ='18-month forecast'!L7*'Model inputs'!U34 -> 1500 | M8: ='18-month forecast'!M7*'Model inputs'!U34 -> 1500 | N8: ='18-month forecast'!N7*'Model inputs'!U34 -> 1500 | O8: ='18-month forecast'!O7*'Model inputs'!U34 -> 1500 | P8: ='18-month forecast'!P7*'Model inputs'!U34 -> 1500 | Q8: ='18-month forecast'!Q7*'Model inputs'!U34 -> 1500 | R8: ='18-month forecast'!R7*'Model inputs'!U34 -> 1500 | S8: ='18-month forecast'!S7*'Model inputs'!U34 -> 1500
A9: Infrastructure expense | B9: =IF('Model inputs'!U8="","",'Model inputs'!U8) -> 200 | C9: =IF('Model inputs'!U8="","",'Model inputs'!U8) -> 200 | D9: =IF('Model inputs'!U8="","",'Model inputs'!U8) -> 200 | E9: =IF('Model inputs'!U8="","",'Model inputs'!U8) -> 200 | F9: =IF('Model inputs'!U8="","",'Model inputs'!U8) -> 200 | G9: =IF('Model inputs'!U8="","",'Model inputs'!U8) -> 200 | H9: =IF('Model inputs'!U8="","",'Model inputs'!U8) -> 200 | I9: =IF('Model inputs'!U8="","",'Model inputs'!U8) -> 200 | J9: =IF('Model inputs'!U8="","",'Model inputs'!U8) -> 200 | K9: =IF('Model inputs'!U8="","",'Model inputs'!U8) -> 200 | L9: =IF('Model inputs'!U8="","",'Model inputs'!U8) -> 200 | M9: =IF('Model inputs'!U8="","",'Model inputs'!U8) -> 200 | N9: =IF('Model inputs'!U8="","",'Model inputs'!U8) -> 200 | O9: =IF('Model inputs'!U8="","",'Model inputs'!U8) -> 200 | P9: =IF('Model inputs'!U8="","",'Model inputs'!U8) -> 200 | Q9: =IF('Model inputs'!U8="","",'Model inputs'!U8) -> 200 | R9: =IF('Model inputs'!U8="","",'Model inputs'!U8) -> 200 | S9: =IF('Model inputs'!U8="","",'Model inputs'!U8) -> 200
A10: Cost of revenue | B10: ='18-month forecast'!B8+'18-month forecast'!B9 -> 1700 | C10: ='18-month forecast'!C8+'18-month forecast'!C9 -> 1700 | D10: ='18-month forecast'!D8+'18-month forecast'!D9 -> 1700 | E10: ='18-month forecast'!E8+'18-month forecast'!E9 -> 1700 | F10: ='18-month forecast'!F8+'18-month forecast'!F9 -> 1700 | G10: ='18-month forecast'!G8+'18-month forecast'!G9 -> 1700 | H10: ='18-month forecast'!H8+'18-month forecast'!H9 -> 1700 | I10: ='18-month forecast'!I8+'18-month forecast'!I9 -> 1700 | ... S10: ='18-month forecast'!S8+'18-month forecast'!S9 -> 1700
A11: Gross profit | B11: ='18-month forecast'!B6-'18-month forecast'!B10 -> 750 | C11: ='18-month forecast'!C6-'18-month forecast'!C10 -> 750 | D11: ='18-month forecast'!D6-'18-month forecast'!D10 -> 750 | E11: ='18-month forecast'!E6-'18-month forecast'!E10 -> 750 | F11: ='18-month forecast'!F6-'18-month forecast'!F10 -> 750 | G11: ='18-month forecast'!G6-'18-month forecast'!G10 -> 750 | H11: ='18-month forecast'!H6-'18-month forecast'!H10 -> 750 | I11: ='18-month forecast'!I6-'18-month forecast'!I10 -> 750 | ... S11: ='18-month forecast'!S6-'18-month forecast'!S10 -> 750
A12: Gross margin | B12: =IFERROR('18-month forecast'!B11/'18-month forecast'!B6,"") -> 0.30612245 | C12: =IFERROR('18-month forecast'!C11/'18-month forecast'!C6,"") -> 0.30612245 | D12: =IFERROR('18-month forecast'!D11/'18-month forecast'!D6,"") -> 0.30612245 | E12: =IFERROR('18-month forecast'!E11/'18-month forecast'!E6,"") -> 0.30612245 | F12: =IFERROR('18-month forecast'!F11/'18-month forecast'!F6,"") -> 0.30612245 | G12: =IFERROR('18-month forecast'!G11/'18-month forecast'!G6,"") -> 0.30612245 | H12: =IFERROR('18-month forecast'!H11/'18-month forecast'!H6,"") -> 0.30612245 | I12: =IFERROR('18-month forecast'!I11/'18-month forecast'!I6,"") -> 0.30612245 | ... S12: =IFERROR('18-month forecast'!S11/'18-month forecast'!S6,"") -> 0.30612245
A13: Founder payroll | B13: =SUM('18-month forecast'!B14,'18-month forecast'!B15,'18-month forecast'!B16,'18-month forecast'!B17) -> 0 | C13: =SUM('18-month forecast'!C14,'18-month forecast'!C15,'18-month forecast'!C16,'18-month forecast'!C17) -> 0 | D13: =SUM('18-month forecast'!D14,'18-month forecast'!D15,'18-month forecast'!D16,'18-month forecast'!D17) -> 0 | E13: =SUM('18-month forecast'!E14,'18-month forecast'!E15,'18-month forecast'!E16,'18-month forecast'!E17) -> 0 | F13: =SUM('18-month forecast'!F14,'18-month forecast'!F15,'18-month forecast'!F16,'18-month forecast'!F17) -> 0 | G13: =SUM('18-month forecast'!G14,'18-month forecast'!G15,'18-month forecast'!G16,'18-month forecast'!G17) -> 0 | H13: =SUM('18-month forecast'!H14,'18-month forecast'!H15,'18-month forecast'!H16,'18-month forecast'!H17) -> 8000 | I13: =SUM('18-month forecast'!I14,'18-month forecast'!I15,'18-month forecast'!I16,'18-month forecast'!I17) -> 8000 | ... S13: =SUM('18-month forecast'!S14,'18-month forecast'!S15,'18-month forecast'!S16,'18-month forecast'!S17) -> 8000
A14: Placeholder founder 1 | B14: =IF(IF(IF(ISERROR(DATE(2026,10,1)>=DATE(YEAR('Model inputs'!U10),MONTH('Model inputs'!U10),1)),DATE(2026,10,1)>=DATE(YEAR('Model inputs'!U10),MONTH('Model inputs'!U10),1),IF(DATE(YEAR('Model inputs'!U10),MONTH('Model inputs'!U10),1)="","",DATE(2026,10,1)>=DATE(YEAR('Model inputs'!U10),MONTH('Model inputs'!U10),1)))="",FALSE,IF(ISERROR(DATE(2026,10,1)>=DATE(YEAR('Model inputs'!U10),MONTH('Model inputs'!U10),1)),DATE(2026,10,1)>=DATE(YEAR('Model inputs'!U10),MONTH('Model inputs'!U10),1),IF(DATE(YEAR('Model inputs'!U10),MONTH('Model inputs'!U10),1)="","",DATE(2026,10,1)>=DATE(YEAR('Model inputs'!U10),MONTH('Model inputs'!U10),1)))),IF('Model inputs'!U23="","",'Model inputs'!U23),0) -> 0 | C14: =IF(IF(IF(ISERROR(DATE(2026,11,1)>=DATE(YEAR('Model inputs'!U10),MONTH('Model inputs'!U10),1)),DATE(2026,11,1)>=DATE(YEAR('Model inputs'!U10),MONTH('Model inputs'!U10),1),IF(DATE(YEAR('Model inputs'!U10),MONTH('Model inputs'!U10),1)="","",DATE(2026,11,1)>=DATE(YEAR('Model inputs'!U10),MONTH('Model inputs'!U10),1)))="",FALSE,IF(ISERROR(DATE(2026,11,1)>=DATE(YEAR('Model inputs'!U10),MONTH('Model inputs'!U10),1)),DATE(2026,11,1)>=DATE(YEAR('Model inputs'!U10),MONTH('Model inputs'!U10),1),IF(DATE(YEAR('Model inputs'!U10),MONTH('Model inputs'!U10),1)="","",DATE(2026,11,1)>=DATE(YEAR('Model inputs'!U10),MONTH('Model inputs'!U10),1)))),IF('Model inputs'!U23="","",'Model inputs'!U23),0) -> 0 | D14: =IF(IF(IF(ISERROR(DATE(2026,12,1)>=DATE(YEAR('Model inputs'!U10),MONTH('Model inputs'!U10),1)),DATE(2026,12,1)>=DATE(YEAR('Model inputs'!U10),MONTH('Model inputs'!U10),1),IF(DATE(YEAR('Model inputs'!U10),MONTH('Model inputs'!U10),1)="","",DATE(2026,12,1)>=DATE(YEAR('Model inputs'!U10),MONTH('Model inputs'!U10),1)))="",FALSE,IF(ISERROR(DATE(2026,12,1)>=DATE(YEAR('Model inputs'!U10),MONTH('Model inputs'!U10),1)),DATE(2026,12,1)>=DATE(YEAR('Model inputs'!U10),MONTH('Model inputs'!U10),1),IF(DATE(YEAR('Model inputs'!U10),MONTH('Model inputs'!U10),1)="","",DATE(2026,12,1)>=DATE(YEAR('Model inputs'!U10),MONTH('Model inputs'!U10),1)))),IF('Model inputs'!U23="","",'Model inputs'!U23),0) -> 0 | E14: =IF(IF(IF(ISERROR(DATE(2027,1,1)>=DATE(YEAR('Model inputs'!U10),MONTH('Model inputs'!U10),1)),DATE(2027,1,1)>=DATE(YEAR('Model inputs'!U10),MONTH('Model inputs'!U10),1),IF(DATE(YEAR('Model inputs'!U10),MONTH('Model inputs'!U10),1)="","",DATE(2027,1,1)>=DATE(YEAR('Model inputs'!U10),MONTH('Model inputs'!U10),1)))="",FALSE,IF(ISERROR(DATE(2027,1,1)>=DATE(YEAR('Model inputs'!U10),MONTH('Model inputs'!U10),1)),DATE(2027,1,1)>=DATE(YEAR('Model inputs'!U10),MONTH('Model inputs'!U10),1),IF(DATE(YEAR('Model inputs'!U10),MONTH('Model inputs'!U10),1)="","",DATE(2027,1,1)>=DATE(YEAR('Model inputs'!U10),MONTH('Model inputs'!U10),1)))),IF('Model inputs'!U23="","",'Model inputs'!U23),0) -> 0 | F14: =IF(IF(IF(ISERROR(DATE(2027,2,1)>=DATE(YEAR('Model inputs'!U10),MONTH('Model inputs'!U10),1)),DATE(2027,2,1)>=DATE(YEAR('Model inputs'!U10),MONTH('Model inputs'!U10),1),IF(DATE(YEAR('Model inputs'!U10),MONTH('Model inputs'!U10),1)="","",DATE(2027,2,1)>=DATE(YEAR('Model inputs'!U10),MONTH('Model inputs'!U10),1)))="",FALSE,IF(ISERROR(DATE(2027,2,1)>=DATE(YEAR('Model inputs'!U10),MONTH('Model inputs'!U10),1)),DATE(2027,2,1)>=DATE(YEAR('Model inputs'!U10),MONTH('Model inputs'!U10),1),IF(DATE(YEAR('Model inputs'!U10),MONTH('Model inputs'!U10),1)="","",DATE(2027,2,1)>=DATE(YEAR('Model inputs'!U10),MONTH('Model inputs'!U10),1)))),IF('Model inputs'!U23="","",'Model inputs'!U23),0) -> 0 | G14: =IF(IF(IF(ISERROR(DATE(2027,3,1)>=DATE(YEAR('Model inputs'!U10),MONTH('Model inputs'!U10),1)),DATE(2027,3,1)>=DATE(YEAR('Model inputs'!U10),MONTH('Model inputs'!U10),1),IF(DATE(YEAR('Model inputs'!U10),MONTH('Model inputs'!U10),1)="","",DATE(2027,3,1)>=DATE(YEAR('Model inputs'!U10),MONTH('Model inputs'!U10),1)))="",FALSE,IF(ISERROR(DATE(2027,3,1)>=DATE(YEAR('Model inputs'!U10),MONTH('Model inputs'!U10),1)),DATE(2027,3,1)>=DATE(YEAR('Model inputs'!U10),MONTH('Model inputs'!U10),1),IF(DATE(YEAR('Model inputs'!U10),MONTH('Model inputs'!U10),1)="","",DATE(2027,3,1)>=DATE(YEAR('Model inputs'!U10),MONTH('Model inputs'!U10),1)))),IF('Model inputs'!U23="","",'Model inputs'!U23),0) -> 0 | H14: =IF(IF(IF(ISERROR(DATE(2027,4,1)>=DATE(YEAR('Model inputs'!U10),MONTH('Model inputs'!U10),1)),DATE(2027,4,1)>=DATE(YEAR('Model inputs'!U10),MONTH('Model inputs'!U10),1),IF(DATE(YEAR('Model inputs'!U10),MONTH('Model inputs'!U10),1)="","",DATE(2027,4,1)>=DATE(YEAR('Model inputs'!U10),MONTH('Model inputs'!U10),1)))="",FALSE,IF(ISERROR(DATE(2027,4,1)>=DATE(YEAR('Model inputs'!U10),MONTH('Model inputs'!U10),1)),DATE(2027,4,1)>=DATE(YEAR('Model inputs'!U10),MONTH('Model inputs'!U10),1),IF(DATE(YEAR('Model inputs'!U10),MONTH('Model inputs'!U10),1)="","",DATE(2027,4,1)>=DATE(YEAR('Model inputs'!U10),MONTH('Model inputs'!U10),1)))),IF('Model inputs'!U23="","",'Model inputs'!U23),0) -> 2000 | I14: =IF(IF(IF(ISERROR(DATE(2027,5,1)>=DATE(YEAR('Model inputs'!U10),MONTH('Model inputs'!U10),1)),DATE(2027,5,1)>=DATE(YEAR('Model inputs'!U10),MONTH('Model inputs'!U10),1),IF(DATE(YEAR('Model inputs'!U10),MONTH('Model inputs'!U10),1)="","",DATE(2027,5,1)>=DATE(YEAR('Model inputs'!U10),MONTH('Model inputs'!U10),1)))="",FALSE,IF(ISERROR(DATE(2027,5,1)>=DATE(YEAR('Model inputs'!U10),MONTH('Model inputs'!U10),1)),DATE(2027,5,1)>=DATE(YEAR('Model inputs'!U10),MONTH('Model inputs'!U10),1),IF(DATE(YEAR('Model inputs'!U10),MONTH('Model inputs'!U10),1)="","",DATE(2027,5,1)>=DATE(YEAR('Model inputs'!U10),MONTH('Model inputs'!U10),1)))),IF('Model inputs'!U23="","",'Model inputs'!U23),0) -> 2000 | J14: =IF(IF(IF(ISERROR(DATE(2027,6,1)>=DATE(YEAR('Model inputs'!U10),MONTH('Model inputs'!U10),1)),DATE(2027,6,1)>=DATE(YEAR('Model inputs'!U10),MONTH('Model inputs'!U10),1),IF(DATE(YEAR('Model inputs'!U10),MONTH('Model inputs'!U10),1)="","",DATE(2027,6,1)>=DATE(YEAR('Model inputs'!U10),MONTH('Model inputs'!U10),1)))="",FALSE,IF(ISERROR(DATE(2027,6,1)>=DATE(YEAR('Model inputs'!U10),MONTH('Model inputs'!U10),1)),DATE(2027,6,1)>=DATE(YEAR('Model inputs'!U10),MONTH('Model inputs'!U10),1),IF(DATE(YEAR('Model inputs'!U10),MONTH('Model inputs'!U10),1)="","",DATE(2027,6,1)>=DATE(YEAR('Model inputs'!U10),MONTH('Model inputs'!U10),1)))),IF('Model inputs'!U23="","",'Model inputs'!U23),0) -> 2000 | K14: =IF(IF(IF(ISERROR(DATE(2027,7,1)>=DATE(YEAR('Model inputs'!U10),MONTH('Model inputs'!U10),1)),DATE(2027,7,1)>=DATE(YEAR('Model inputs'!U10),MONTH('Model inputs'!U10),1),IF(DATE(YEAR('Model inputs'!U10),MONTH('Model inputs'!U10),1)="","",DATE(2027,7,1)>=DATE(YEAR('Model inputs'!U10),MONTH('Model inputs'!U10),1)))="",FALSE,IF(ISERROR(DATE(2027,7,1)>=DATE(YEAR('Model inputs'!U10),MONTH('Model inputs'!U10),1)),DATE(2027,7,1)>=DATE(YEAR('Model inputs'!U10),MONTH('Model inputs'!U10),1),IF(DATE(YEAR('Model inputs'!U10),MONTH('Model inputs'!U10),1)="","",DATE(2027,7,1)>=DATE(YEAR('Model inputs'!U10),MONTH('Model inputs'!U10),1)))),IF('Model inputs'!U23="","",'Model inputs'!U23),0) -> 2000 | L14: =IF(IF(IF(ISERROR(DATE(2027,8,1)>=DATE(YEAR('Model inputs'!U10),MONTH('Model inputs'!U10),1)),DATE(2027,8,1)>=DATE(YEAR('Model inputs'!U10),MONTH('Model inputs'!U10),1),IF(DATE(YEAR('Model inputs'!U10),MONTH('Model inputs'!U10),1)="","",DATE(2027,8,1)>=DATE(YEAR('Model inputs'!U10),MONTH('Model inputs'!U10),1)))="",FALSE,IF(ISERROR(DATE(2027,8,1)>=DATE(YEAR('Model inputs'!U10),MONTH('Model inputs'!U10),1)),DATE(2027,8,1)>=DATE(YEAR('Model inputs'!U10),MONTH('Model inputs'!U10),1),IF(DATE(YEAR('Model inputs'!U10),MONTH('Model inputs'!U10),1)="","",DATE(2027,8,1)>=DATE(YEAR('Model inputs'!U10),MONTH('Model inputs'!U10),1)))),IF('Model inputs'!U23="","",'Model inputs'!U23),0) -> 2000 | M14: =IF(IF(IF(ISERROR(DATE(2027,9,1)>=DATE(YEAR('Model inputs'!U10),MONTH('Model inputs'!U10),1)),DATE(2027,9,1)>=DATE(YEAR('Model inputs'!U10),MONTH('Model inputs'!U10),1),IF(DATE(YEAR('Model inputs'!U10),MONTH('Model inputs'!U10),1)="","",DATE(2027,9,1)>=DATE(YEAR('Model inputs'!U10),MONTH('Model inputs'!U10),1)))="",FALSE,IF(ISERROR(DATE(2027,9,1)>=DATE(YEAR('Model inputs'!U10),MONTH('Model inputs'!U10),1)),DATE(2027,9,1)>=DATE(YEAR('Model inputs'!U10),MONTH('Model inputs'!U10),1),IF(DATE(YEAR('Model inputs'!U10),MONTH('Model inputs'!U10),1)="","",DATE(2027,9,1)>=DATE(YEAR('Model inputs'!U10),MONTH('Model inputs'!U10),1)))),IF('Model inputs'!U23="","",'Model inputs'!U23),0) -> 2000 | N14: =IF(IF(IF(ISERROR(DATE(2027,10,1)>=DATE(YEAR('Model inputs'!U10),MONTH('Model inputs'!U10),1)),DATE(2027,10,1)>=DATE(YEAR('Model inputs'!U10),MONTH('Model inputs'!U10),1),IF(DATE(YEAR('Model inputs'!U10),MONTH('Model inputs'!U10),1)="","",DATE(2027,10,1)>=DATE(YEAR('Model inputs'!U10),MONTH('Model inputs'!U10),1)))="",FALSE,IF(ISERROR(DATE(2027,10,1)>=DATE(YEAR('Model inputs'!U10),MONTH('Model inputs'!U10),1)),DATE(2027,10,1)>=DATE(YEAR('Model inputs'!U10),MONTH('Model inputs'!U10),1),IF(DATE(YEAR('Model inputs'!U10),MONTH('Model inputs'!U10),1)="","",DATE(2027,10,1)>=DATE(YEAR('Model inputs'!U10),MONTH('Model inputs'!U10),1)))),IF('Model inputs'!U23="","",'Model inputs'!U23),0) -> 2000 | O14: =IF(IF(IF(ISERROR(DATE(2027,11,1)>=DATE(YEAR('Model inputs'!U10),MONTH('Model inputs'!U10),1)),DATE(2027,11,1)>=DATE(YEAR('Model inputs'!U10),MONTH('Model inputs'!U10),1),IF(DATE(YEAR('Model inputs'!U10),MONTH('Model inputs'!U10),1)="","",DATE(2027,11,1)>=DATE(YEAR('Model inputs'!U10),MONTH('Model inputs'!U10),1)))="",FALSE,IF(ISERROR(DATE(2027,11,1)>=DATE(YEAR('Model inputs'!U10),MONTH('Model inputs'!U10),1)),DATE(2027,11,1)>=DATE(YEAR('Model inputs'!U10),MONTH('Model inputs'!U10),1),IF(DATE(YEAR('Model inputs'!U10),MONTH('Model inputs'!U10),1)="","",DATE(2027,11,1)>=DATE(YEAR('Model inputs'!U10),MONTH('Model inputs'!U10),1)))),IF('Model inputs'!U23="","",'Model inputs'!U23),0) -> 2000 | P14: =IF(IF(IF(ISERROR(DATE(2027,12,1)>=DATE(YEAR('Model inputs'!U10),MONTH('Model inputs'!U10),1)),DATE(2027,12,1)>=DATE(YEAR('Model inputs'!U10),MONTH('Model inputs'!U10),1),IF(DATE(YEAR('Model inputs'!U10),MONTH('Model inputs'!U10),1)="","",DATE(2027,12,1)>=DATE(YEAR('Model inputs'!U10),MONTH('Model inputs'!U10),1)))="",FALSE,IF(ISERROR(DATE(2027,12,1)>=DATE(YEAR('Model inputs'!U10),MONTH('Model inputs'!U10),1)),DATE(2027,12,1)>=DATE(YEAR('Model inputs'!U10),MONTH('Model inputs'!U10),1),IF(DATE(YEAR('Model inputs'!U10),MONTH('Model inputs'!U10),1)="","",DATE(2027,12,1)>=DATE(YEAR('Model inputs'!U10),MONTH('Model inputs'!U10),1)))),IF('Model inputs'!U23="","",'Model inputs'!U23),0) -> 2000 | Q14: =IF(IF(IF(ISERROR(DATE(2028,1,1)>=DATE(YEAR('Model inputs'!U10),MONTH('Model inputs'!U10),1)),DATE(2028,1,1)>=DATE(YEAR('Model inputs'!U10),MONTH('Model inputs'!U10),1),IF(DATE(YEAR('Model inputs'!U10),MONTH('Model inputs'!U10),1)="","",DATE(2028,1,1)>=DATE(YEAR('Model inputs'!U10),MONTH('Model inputs'!U10),1)))="",FALSE,IF(ISERROR(DATE(2028,1,1)>=DATE(YEAR('Model inputs'!U10),MONTH('Model inputs'!U10),1)),DATE(2028,1,1)>=DATE(YEAR('Model inputs'!U10),MONTH('Model inputs'!U10),1),IF(DATE(YEAR('Model inputs'!U10),MONTH('Model inputs'!U10),1)="","",DATE(2028,1,1)>=DATE(YEAR('Model inputs'!U10),MONTH('Model inputs'!U10),1)))),IF('Model inputs'!U23="","",'Model inputs'!U23),0) -> 2000 | R14: =IF(IF(IF(ISERROR(DATE(2028,2,1)>=DATE(YEAR('Model inputs'!U10),MONTH('Model inputs'!U10),1)),DATE(2028,2,1)>=DATE(YEAR('Model inputs'!U10),MONTH('Model inputs'!U10),1),IF(DATE(YEAR('Model inputs'!U10),MONTH('Model inputs'!U10),1)="","",DATE(2028,2,1)>=DATE(YEAR('Model inputs'!U10),MONTH('Model inputs'!U10),1)))="",FALSE,IF(ISERROR(DATE(2028,2,1)>=DATE(YEAR('Model inputs'!U10),MONTH('Model inputs'!U10),1)),DATE(2028,2,1)>=DATE(YEAR('Model inputs'!U10),MONTH('Model inputs'!U10),1),IF(DATE(YEAR('Model inputs'!U10),MONTH('Model inputs'!U10),1)="","",DATE(2028,2,1)>=DATE(YEAR('Model inputs'!U10),MONTH('Model inputs'!U10),1)))),IF('Model inputs'!U23="","",'Model inputs'!U23),0) -> 2000 | S14: =IF(IF(IF(ISERROR(DATE(2028,3,1)>=DATE(YEAR('Model inputs'!U10),MONTH('Model inputs'!U10),1)),DATE(2028,3,1)>=DATE(YEAR('Model inputs'!U10),MONTH('Model inputs'!U10),1),IF(DATE(YEAR('Model inputs'!U10),MONTH('Model inputs'!U10),1)="","",DATE(2028,3,1)>=DATE(YEAR('Model inputs'!U10),MONTH('Model inputs'!U10),1)))="",FALSE,IF(ISERROR(DATE(2028,3,1)>=DATE(YEAR('Model inputs'!U10),MONTH('Model inputs'!U10),1)),DATE(2028,3,1)>=DATE(YEAR('Model inputs'!U10),MONTH('Model inputs'!U10),1),IF(DATE(YEAR('Model inputs'!U10),MONTH('Model inputs'!U10),1)="","",DATE(2028,3,1)>=DATE(YEAR('Model inputs'!U10),MONTH('Model inputs'!U10),1)))),IF('Model inputs'!U23="","",'Model inputs'!U23),0) -> 2000
A15: Placeholder founder 2 | B15: =IF(IF(IF(ISERROR(DATE(2026,10,1)>=DATE(YEAR('Model inputs'!U11),MONTH('Model inputs'!U11),1)),DATE(2026,10,1)>=DATE(YEAR('Model inputs'!U11),MONTH('Model inputs'!U11),1),IF(DATE(YEAR('Model inputs'!U11),MONTH('Model inputs'!U11),1)="","",DATE(2026,10,1)>=DATE(YEAR('Model inputs'!U11),MONTH('Model inputs'!U11),1)))="",FALSE,IF(ISERROR(DATE(2026,10,1)>=DATE(YEAR('Model inputs'!U11),MONTH('Model inputs'!U11),1)),DATE(2026,10,1)>=DATE(YEAR('Model inputs'!U11),MONTH('Model inputs'!U11),1),IF(DATE(YEAR('Model inputs'!U11),MONTH('Model inputs'!U11),1)="","",DATE(2026,10,1)>=DATE(YEAR('Model inputs'!U11),MONTH('Model inputs'!U11),1)))),IF('Model inputs'!U24="","",'Model inputs'!U24),0) -> 0 | C15: =IF(IF(IF(ISERROR(DATE(2026,11,1)>=DATE(YEAR('Model inputs'!U11),MONTH('Model inputs'!U11),1)),DATE(2026,11,1)>=DATE(YEAR('Model inputs'!U11),MONTH('Model inputs'!U11),1),IF(DATE(YEAR('Model inputs'!U11),MONTH('Model inputs'!U11),1)="","",DATE(2026,11,1)>=DATE(YEAR('Model inputs'!U11),MONTH('Model inputs'!U11),1)))="",FALSE,IF(ISERROR(DATE(2026,11,1)>=DATE(YEAR('Model inputs'!U11),MONTH('Model inputs'!U11),1)),DATE(2026,11,1)>=DATE(YEAR('Model inputs'!U11),MONTH('Model inputs'!U11),1),IF(DATE(YEAR('Model inputs'!U11),MONTH('Model inputs'!U11),1)="","",DATE(2026,11,1)>=DATE(YEAR('Model inputs'!U11),MONTH('Model inputs'!U11),1)))),IF('Model inputs'!U24="","",'Model inputs'!U24),0) -> 0 | D15: =IF(IF(IF(ISERROR(DATE(2026,12,1)>=DATE(YEAR('Model inputs'!U11),MONTH('Model inputs'!U11),1)),DATE(2026,12,1)>=DATE(YEAR('Model inputs'!U11),MONTH('Model inputs'!U11),1),IF(DATE(YEAR('Model inputs'!U11),MONTH('Model inputs'!U11),1)="","",DATE(2026,12,1)>=DATE(YEAR('Model inputs'!U11),MONTH('Model inputs'!U11),1)))="",FALSE,IF(ISERROR(DATE(2026,12,1)>=DATE(YEAR('Model inputs'!U11),MONTH('Model inputs'!U11),1)),DATE(2026,12,1)>=DATE(YEAR('Model inputs'!U11),MONTH('Model inputs'!U11),1),IF(DATE(YEAR('Model inputs'!U11),MONTH('Model inputs'!U11),1)="","",DATE(2026,12,1)>=DATE(YEAR('Model inputs'!U11),MONTH('Model inputs'!U11),1)))),IF('Model inputs'!U24="","",'Model inputs'!U24),0) -> 0 | E15: =IF(IF(IF(ISERROR(DATE(2027,1,1)>=DATE(YEAR('Model inputs'!U11),MONTH('Model inputs'!U11),1)),DATE(2027,1,1)>=DATE(YEAR('Model inputs'!U11),MONTH('Model inputs'!U11),1),IF(DATE(YEAR('Model inputs'!U11),MONTH('Model inputs'!U11),1)="","",DATE(2027,1,1)>=DATE(YEAR('Model inputs'!U11),MONTH('Model inputs'!U11),1)))="",FALSE,IF(ISERROR(DATE(2027,1,1)>=DATE(YEAR('Model inputs'!U11),MONTH('Model inputs'!U11),1)),DATE(2027,1,1)>=DATE(YEAR('Model inputs'!U11),MONTH('Model inputs'!U11),1),IF(DATE(YEAR('Model inputs'!U11),MONTH('Model inputs'!U11),1)="","",DATE(2027,1,1)>=DATE(YEAR('Model inputs'!U11),MONTH('Model inputs'!U11),1)))),IF('Model inputs'!U24="","",'Model inputs'!U24),0) -> 0 | F15: =IF(IF(IF(ISERROR(DATE(2027,2,1)>=DATE(YEAR('Model inputs'!U11),MONTH('Model inputs'!U11),1)),DATE(2027,2,1)>=DATE(YEAR('Model inputs'!U11),MONTH('Model inputs'!U11),1),IF(DATE(YEAR('Model inputs'!U11),MONTH('Model inputs'!U11),1)="","",DATE(2027,2,1)>=DATE(YEAR('Model inputs'!U11),MONTH('Model inputs'!U11),1)))="",FALSE,IF(ISERROR(DATE(2027,2,1)>=DATE(YEAR('Model inputs'!U11),MONTH('Model inputs'!U11),1)),DATE(2027,2,1)>=DATE(YEAR('Model inputs'!U11),MONTH('Model inputs'!U11),1),IF(DATE(YEAR('Model inputs'!U11),MONTH('Model inputs'!U11),1)="","",DATE(2027,2,1)>=DATE(YEAR('Model inputs'!U11),MONTH('Model inputs'!U11),1)))),IF('Model inputs'!U24="","",'Model inputs'!U24),0) -> 0 | G15: =IF(IF(IF(ISERROR(DATE(2027,3,1)>=DATE(YEAR('Model inputs'!U11),MONTH('Model inputs'!U11),1)),DATE(2027,3,1)>=DATE(YEAR('Model inputs'!U11),MONTH('Model inputs'!U11),1),IF(DATE(YEAR('Model inputs'!U11),MONTH('Model inputs'!U11),1)="","",DATE(2027,3,1)>=DATE(YEAR('Model inputs'!U11),MONTH('Model inputs'!U11),1)))="",FALSE,IF(ISERROR(DATE(2027,3,1)>=DATE(YEAR('Model inputs'!U11),MONTH('Model inputs'!U11),1)),DATE(2027,3,1)>=DATE(YEAR('Model inputs'!U11),MONTH('Model inputs'!U11),1),IF(DATE(YEAR('Model inputs'!U11),MONTH('Model inputs'!U11),1)="","",DATE(2027,3,1)>=DATE(YEAR('Model inputs'!U11),MONTH('Model inputs'!U11),1)))),IF('Model inputs'!U24="","",'Model inputs'!U24),0) -> 0 | H15: =IF(IF(IF(ISERROR(DATE(2027,4,1)>=DATE(YEAR('Model inputs'!U11),MONTH('Model inputs'!U11),1)),DATE(2027,4,1)>=DATE(YEAR('Model inputs'!U11),MONTH('Model inputs'!U11),1),IF(DATE(YEAR('Model inputs'!U11),MONTH('Model inputs'!U11),1)="","",DATE(2027,4,1)>=DATE(YEAR('Model inputs'!U11),MONTH('Model inputs'!U11),1)))="",FALSE,IF(ISERROR(DATE(2027,4,1)>=DATE(YEAR('Model inputs'!U11),MONTH('Model inputs'!U11),1)),DATE(2027,4,1)>=DATE(YEAR('Model inputs'!U11),MONTH('Model inputs'!U11),1),IF(DATE(YEAR('Model inputs'!U11),MONTH('Model inputs'!U11),1)="","",DATE(2027,4,1)>=DATE(YEAR('Model inputs'!U11),MONTH('Model inputs'!U11),1)))),IF('Model inputs'!U24="","",'Model inputs'!U24),0) -> 2000 | I15: =IF(IF(IF(ISERROR(DATE(2027,5,1)>=DATE(YEAR('Model inputs'!U11),MONTH('Model inputs'!U11),1)),DATE(2027,5,1)>=DATE(YEAR('Model inputs'!U11),MONTH('Model inputs'!U11),1),IF(DATE(YEAR('Model inputs'!U11),MONTH('Model inputs'!U11),1)="","",DATE(2027,5,1)>=DATE(YEAR('Model inputs'!U11),MONTH('Model inputs'!U11),1)))="",FALSE,IF(ISERROR(DATE(2027,5,1)>=DATE(YEAR('Model inputs'!U11),MONTH('Model inputs'!U11),1)),DATE(2027,5,1)>=DATE(YEAR('Model inputs'!U11),MONTH('Model inputs'!U11),1),IF(DATE(YEAR('Model inputs'!U11),MONTH('Model inputs'!U11),1)="","",DATE(2027,5,1)>=DATE(YEAR('Model inputs'!U11),MONTH('Model inputs'!U11),1)))),IF('Model inputs'!U24="","",'Model inputs'!U24),0) -> 2000 | J15: =IF(IF(IF(ISERROR(DATE(2027,6,1)>=DATE(YEAR('Model inputs'!U11),MONTH('Model inputs'!U11),1)),DATE(2027,6,1)>=DATE(YEAR('Model inputs'!U11),MONTH('Model inputs'!U11),1),IF(DATE(YEAR('Model inputs'!U11),MONTH('Model inputs'!U11),1)="","",DATE(2027,6,1)>=DATE(YEAR('Model inputs'!U11),MONTH('Model inputs'!U11),1)))="",FALSE,IF(ISERROR(DATE(2027,6,1)>=DATE(YEAR('Model inputs'!U11),MONTH('Model inputs'!U11),1)),DATE(2027,6,1)>=DATE(YEAR('Model inputs'!U11),MONTH('Model inputs'!U11),1),IF(DATE(YEAR('Model inputs'!U11),MONTH('Model inputs'!U11),1)="","",DATE(2027,6,1)>=DATE(YEAR('Model inputs'!U11),MONTH('Model inputs'!U11),1)))),IF('Model inputs'!U24="","",'Model inputs'!U24),0) -> 2000 | K15: =IF(IF(IF(ISERROR(DATE(2027,7,1)>=DATE(YEAR('Model inputs'!U11),MONTH('Model inputs'!U11),1)),DATE(2027,7,1)>=DATE(YEAR('Model inputs'!U11),MONTH('Model inputs'!U11),1),IF(DATE(YEAR('Model inputs'!U11),MONTH('Model inputs'!U11),1)="","",DATE(2027,7,1)>=DATE(YEAR('Model inputs'!U11),MONTH('Model inputs'!U11),1)))="",FALSE,IF(ISERROR(DATE(2027,7,1)>=DATE(YEAR('Model inputs'!U11),MONTH('Model inputs'!U11),1)),DATE(2027,7,1)>=DATE(YEAR('Model inputs'!U11),MONTH('Model inputs'!U11),1),IF(DATE(YEAR('Model inputs'!U11),MONTH('Model inputs'!U11),1)="","",DATE(2027,7,1)>=DATE(YEAR('Model inputs'!U11),MONTH('Model inputs'!U11),1)))),IF('Model inputs'!U24="","",'Model inputs'!U24),0) -> 2000 | L15: =IF(IF(IF(ISERROR(DATE(2027,8,1)>=DATE(YEAR('Model inputs'!U11),MONTH('Model inputs'!U11),1)),DATE(2027,8,1)>=DATE(YEAR('Model inputs'!U11),MONTH('Model inputs'!U11),1),IF(DATE(YEAR('Model inputs'!U11),MONTH('Model inputs'!U11),1)="","",DATE(2027,8,1)>=DATE(YEAR('Model inputs'!U11),MONTH('Model inputs'!U11),1)))="",FALSE,IF(ISERROR(DATE(2027,8,1)>=DATE(YEAR('Model inputs'!U11),MONTH('Model inputs'!U11),1)),DATE(2027,8,1)>=DATE(YEAR('Model inputs'!U11),MONTH('Model inputs'!U11),1),IF(DATE(YEAR('Model inputs'!U11),MONTH('Model inputs'!U11),1)="","",DATE(2027,8,1)>=DATE(YEAR('Model inputs'!U11),MONTH('Model inputs'!U11),1)))),IF('Model inputs'!U24="","",'Model inputs'!U24),0) -> 2000 | M15: =IF(IF(IF(ISERROR(DATE(2027,9,1)>=DATE(YEAR('Model inputs'!U11),MONTH('Model inputs'!U11),1)),DATE(2027,9,1)>=DATE(YEAR('Model inputs'!U11),MONTH('Model inputs'!U11),1),IF(DATE(YEAR('Model inputs'!U11),MONTH('Model inputs'!U11),1)="","",DATE(2027,9,1)>=DATE(YEAR('Model inputs'!U11),MONTH('Model inputs'!U11),1)))="",FALSE,IF(ISERROR(DATE(2027,9,1)>=DATE(YEAR('Model inputs'!U11),MONTH('Model inputs'!U11),1)),DATE(2027,9,1)>=DATE(YEAR('Model inputs'!U11),MONTH('Model inputs'!U11),1),IF(DATE(YEAR('Model inputs'!U11),MONTH('Model inputs'!U11),1)="","",DATE(2027,9,1)>=DATE(YEAR('Model inputs'!U11),MONTH('Model inputs'!U11),1)))),IF('Model inputs'!U24="","",'Model inputs'!U24),0) -> 2000 | N15: =IF(IF(IF(ISERROR(DATE(2027,10,1)>=DATE(YEAR('Model inputs'!U11),MONTH('Model inputs'!U11),1)),DATE(2027,10,1)>=DATE(YEAR('Model inputs'!U11),MONTH('Model inputs'!U11),1),IF(DATE(YEAR('Model inputs'!U11),MONTH('Model inputs'!U11),1)="","",DATE(2027,10,1)>=DATE(YEAR('Model inputs'!U11),MONTH('Model inputs'!U11),1)))="",FALSE,IF(ISERROR(DATE(2027,10,1)>=DATE(YEAR('Model inputs'!U11),MONTH('Model inputs'!U11),1)),DATE(2027,10,1)>=DATE(YEAR('Model inputs'!U11),MONTH('Model inputs'!U11),1),IF(DATE(YEAR('Model inputs'!U11),MONTH('Model inputs'!U11),1)="","",DATE(2027,10,1)>=DATE(YEAR('Model inputs'!U11),MONTH('Model inputs'!U11),1)))),IF('Model inputs'!U24="","",'Model inputs'!U24),0) -> 2000 | O15: =IF(IF(IF(ISERROR(DATE(2027,11,1)>=DATE(YEAR('Model inputs'!U11),MONTH('Model inputs'!U11),1)),DATE(2027,11,1)>=DATE(YEAR('Model inputs'!U11),MONTH('Model inputs'!U11),1),IF(DATE(YEAR('Model inputs'!U11),MONTH('Model inputs'!U11),1)="","",DATE(2027,11,1)>=DATE(YEAR('Model inputs'!U11),MONTH('Model inputs'!U11),1)))="",FALSE,IF(ISERROR(DATE(2027,11,1)>=DATE(YEAR('Model inputs'!U11),MONTH('Model inputs'!U11),1)),DATE(2027,11,1)>=DATE(YEAR('Model inputs'!U11),MONTH('Model inputs'!U11),1),IF(DATE(YEAR('Model inputs'!U11),MONTH('Model inputs'!U11),1)="","",DATE(2027,11,1)>=DATE(YEAR('Model inputs'!U11),MONTH('Model inputs'!U11),1)))),IF('Model inputs'!U24="","",'Model inputs'!U24),0) -> 2000 | P15: =IF(IF(IF(ISERROR(DATE(2027,12,1)>=DATE(YEAR('Model inputs'!U11),MONTH('Model inputs'!U11),1)),DATE(2027,12,1)>=DATE(YEAR('Model inputs'!U11),MONTH('Model inputs'!U11),1),IF(DATE(YEAR('Model inputs'!U11),MONTH('Model inputs'!U11),1)="","",DATE(2027,12,1)>=DATE(YEAR('Model inputs'!U11),MONTH('Model inputs'!U11),1)))="",FALSE,IF(ISERROR(DATE(2027,12,1)>=DATE(YEAR('Model inputs'!U11),MONTH('Model inputs'!U11),1)),DATE(2027,12,1)>=DATE(YEAR('Model inputs'!U11),MONTH('Model inputs'!U11),1),IF(DATE(YEAR('Model inputs'!U11),MONTH('Model inputs'!U11),1)="","",DATE(2027,12,1)>=DATE(YEAR('Model inputs'!U11),MONTH('Model inputs'!U11),1)))),IF('Model inputs'!U24="","",'Model inputs'!U24),0) -> 2000 | Q15: =IF(IF(IF(ISERROR(DATE(2028,1,1)>=DATE(YEAR('Model inputs'!U11),MONTH('Model inputs'!U11),1)),DATE(2028,1,1)>=DATE(YEAR('Model inputs'!U11),MONTH('Model inputs'!U11),1),IF(DATE(YEAR('Model inputs'!U11),MONTH('Model inputs'!U11),1)="","",DATE(2028,1,1)>=DATE(YEAR('Model inputs'!U11),MONTH('Model inputs'!U11),1)))="",FALSE,IF(ISERROR(DATE(2028,1,1)>=DATE(YEAR('Model inputs'!U11),MONTH('Model inputs'!U11),1)),DATE(2028,1,1)>=DATE(YEAR('Model inputs'!U11),MONTH('Model inputs'!U11),1),IF(DATE(YEAR('Model inputs'!U11),MONTH('Model inputs'!U11),1)="","",DATE(2028,1,1)>=DATE(YEAR('Model inputs'!U11),MONTH('Model inputs'!U11),1)))),IF('Model inputs'!U24="","",'Model inputs'!U24),0) -> 2000 | R15: =IF(IF(IF(ISERROR(DATE(2028,2,1)>=DATE(YEAR('Model inputs'!U11),MONTH('Model inputs'!U11),1)),DATE(2028,2,1)>=DATE(YEAR('Model inputs'!U11),MONTH('Model inputs'!U11),1),IF(DATE(YEAR('Model inputs'!U11),MONTH('Model inputs'!U11),1)="","",DATE(2028,2,1)>=DATE(YEAR('Model inputs'!U11),MONTH('Model inputs'!U11),1)))="",FALSE,IF(ISERROR(DATE(2028,2,1)>=DATE(YEAR('Model inputs'!U11),MONTH('Model inputs'!U11),1)),DATE(2028,2,1)>=DATE(YEAR('Model inputs'!U11),MONTH('Model inputs'!U11),1),IF(DATE(YEAR('Model inputs'!U11),MONTH('Model inputs'!U11),1)="","",DATE(2028,2,1)>=DATE(YEAR('Model inputs'!U11),MONTH('Model inputs'!U11),1)))),IF('Model inputs'!U24="","",'Model inputs'!U24),0) -> 2000 | S15: =IF(IF(IF(ISERROR(DATE(2028,3,1)>=DATE(YEAR('Model inputs'!U11),MONTH('Model inputs'!U11),1)),DATE(2028,3,1)>=DATE(YEAR('Model inputs'!U11),MONTH('Model inputs'!U11),1),IF(DATE(YEAR('Model inputs'!U11),MONTH('Model inputs'!U11),1)="","",DATE(2028,3,1)>=DATE(YEAR('Model inputs'!U11),MONTH('Model inputs'!U11),1)))="",FALSE,IF(ISERROR(DATE(2028,3,1)>=DATE(YEAR('Model inputs'!U11),MONTH('Model inputs'!U11),1)),DATE(2028,3,1)>=DATE(YEAR('Model inputs'!U11),MONTH('Model inputs'!U11),1),IF(DATE(YEAR('Model inputs'!U11),MONTH('Model inputs'!U11),1)="","",DATE(2028,3,1)>=DATE(YEAR('Model inputs'!U11),MONTH('Model inputs'!U11),1)))),IF('Model inputs'!U24="","",'Model inputs'!U24),0) -> 2000
